{"uuid": "d4ce96c9-6719-40d2-89a4-52708a95e9eb", "children": ["ea90cb11-3bbb-4511-981e-96e9a5b466de"], "befores": [{"name": "driver", "status": "broken", "statusDetails": {"message": "selenium.common.exceptions.WebDriverException: Message: 'path' executable may have wrong permissions. Please see https://sites.google.com/a/chromium.org/chromedriver/home\n\n", "trace": "  File \"C:\\Python36-32\\lib\\site-packages\\pluggy\\callers.py\", line 180, in _multicall\n    res = hook_impl.function(*args)\n  File \"C:\\Python36-32\\lib\\site-packages\\_pytest\\fixtures.py\", line 870, in pytest_fixture_setup\n    result = call_fixture_func(fixturefunc, request, kwargs)\n  File \"C:\\Python36-32\\lib\\site-packages\\_pytest\\fixtures.py\", line 739, in call_fixture_func\n    res = next(it)\n  File \"C:\\Python36-32\\lib\\site-packages\\pytest_selenium\\pytest_selenium.py\", line 174, in driver\n    driver = driver_class(**driver_kwargs)\n  File \"C:\\Python36-32\\lib\\site-packages\\selenium\\webdriver\\chrome\\webdriver.py\", line 73, in __init__\n    self.service.start()\n  File \"C:\\Python36-32\\lib\\site-packages\\selenium\\webdriver\\common\\service.py\", line 88, in start\n    os.path.basename(self.path), self.start_error_message)\n"}, "start": 1543077180281, "stop": 1543077180283}], "start": 1543077180281, "stop": 1543077180834}